Traceback (most recent call last):
  File "C:\Users\egoro\miniconda3\lib\site-packages\jupyter_cache\executors\utils.py", line 58, in single_nb_execution
    executenb(
  File "C:\Users\egoro\miniconda3\lib\site-packages\nbclient\client.py", line 1265, in execute
    return NotebookClient(nb=nb, resources=resources, km=km, **kwargs).execute()
  File "C:\Users\egoro\miniconda3\lib\site-packages\jupyter_core\utils\__init__.py", line 166, in wrapped
    return loop.run_until_complete(inner)
  File "C:\Users\egoro\miniconda3\lib\asyncio\base_events.py", line 649, in run_until_complete
    return future.result()
  File "C:\Users\egoro\miniconda3\lib\site-packages\nbclient\client.py", line 703, in async_execute
    await self.async_execute_cell(
  File "C:\Users\egoro\miniconda3\lib\site-packages\nbclient\client.py", line 1021, in async_execute_cell
    await self._check_raise_for_error(cell, cell_index, exec_reply)
  File "C:\Users\egoro\miniconda3\lib\site-packages\nbclient\client.py", line 915, in _check_raise_for_error
    raise CellExecutionError.from_cell_and_msg(cell, exec_reply_content)
nbclient.exceptions.CellExecutionError: An error occurred while executing the following cell:
------------------
#Adding the number of family a passenger had onboard
titanic_df['ModeofTravel'] = titanic_df['ModeofTravel'].apply(lambda x: 'With Someone' if x > 0 else 'Alone')
------------------

[1;31m---------------------------------------------------------------------------[0m
[1;31mKeyError[0m                                  Traceback (most recent call last)
File [1;32m~\miniconda3\lib\site-packages\pandas\core\indexes\base.py:3802[0m, in [0;36mIndex.get_loc[1;34m(self, key, method, tolerance)[0m
[0;32m   3801[0m [38;5;28;01mtry[39;00m:
[1;32m-> 3802[0m     [38;5;28;01mreturn[39;00m [38;5;28;43mself[39;49m[38;5;241;43m.[39;49m[43m_engine[49m[38;5;241;43m.[39;49m[43mget_loc[49m[43m([49m[43mcasted_key[49m[43m)[49m
[0;32m   3803[0m [38;5;28;01mexcept[39;00m [38;5;167;01mKeyError[39;00m [38;5;28;01mas[39;00m err:

File [1;32m~\miniconda3\lib\site-packages\pandas\_libs\index.pyx:138[0m, in [0;36mpandas._libs.index.IndexEngine.get_loc[1;34m()[0m

File [1;32m~\miniconda3\lib\site-packages\pandas\_libs\index.pyx:165[0m, in [0;36mpandas._libs.index.IndexEngine.get_loc[1;34m()[0m

File [1;32mpandas\_libs\hashtable_class_helper.pxi:5745[0m, in [0;36mpandas._libs.hashtable.PyObjectHashTable.get_item[1;34m()[0m

File [1;32mpandas\_libs\hashtable_class_helper.pxi:5753[0m, in [0;36mpandas._libs.hashtable.PyObjectHashTable.get_item[1;34m()[0m

[1;31mKeyError[0m: 'ModeofTravel'

The above exception was the direct cause of the following exception:

[1;31mKeyError[0m                                  Traceback (most recent call last)
Cell [1;32mIn[10], line 2[0m
[0;32m      1[0m [38;5;66;03m#Adding the number of family a passenger had onboard[39;00m
[1;32m----> 2[0m titanic_df[[38;5;124m'[39m[38;5;124mModeofTravel[39m[38;5;124m'[39m] [38;5;241m=[39m [43mtitanic_df[49m[43m[[49m[38;5;124;43m'[39;49m[38;5;124;43mModeofTravel[39;49m[38;5;124;43m'[39;49m[43m][49m[38;5;241m.[39mapply([38;5;28;01mlambda[39;00m x: [38;5;124m'[39m[38;5;124mWith Someone[39m[38;5;124m'[39m [38;5;28;01mif[39;00m x [38;5;241m>[39m [38;5;241m0[39m [38;5;28;01melse[39;00m [38;5;124m'[39m[38;5;124mAlone[39m[38;5;124m'[39m)

File [1;32m~\miniconda3\lib\site-packages\pandas\core\frame.py:3807[0m, in [0;36mDataFrame.__getitem__[1;34m(self, key)[0m
[0;32m   3805[0m [38;5;28;01mif[39;00m [38;5;28mself[39m[38;5;241m.[39mcolumns[38;5;241m.[39mnlevels [38;5;241m>[39m [38;5;241m1[39m:
[0;32m   3806[0m     [38;5;28;01mreturn[39;00m [38;5;28mself[39m[38;5;241m.[39m_getitem_multilevel(key)
[1;32m-> 3807[0m indexer [38;5;241m=[39m [38;5;28;43mself[39;49m[38;5;241;43m.[39;49m[43mcolumns[49m[38;5;241;43m.[39;49m[43mget_loc[49m[43m([49m[43mkey[49m[43m)[49m
[0;32m   3808[0m [38;5;28;01mif[39;00m is_integer(indexer):
[0;32m   3809[0m     indexer [38;5;241m=[39m [indexer]

File [1;32m~\miniconda3\lib\site-packages\pandas\core\indexes\base.py:3804[0m, in [0;36mIndex.get_loc[1;34m(self, key, method, tolerance)[0m
[0;32m   3802[0m     [38;5;28;01mreturn[39;00m [38;5;28mself[39m[38;5;241m.[39m_engine[38;5;241m.[39mget_loc(casted_key)
[0;32m   3803[0m [38;5;28;01mexcept[39;00m [38;5;167;01mKeyError[39;00m [38;5;28;01mas[39;00m err:
[1;32m-> 3804[0m     [38;5;28;01mraise[39;00m [38;5;167;01mKeyError[39;00m(key) [38;5;28;01mfrom[39;00m [38;5;21;01merr[39;00m
[0;32m   3805[0m [38;5;28;01mexcept[39;00m [38;5;167;01mTypeError[39;00m:
[0;32m   3806[0m     [38;5;66;03m# If we have a listlike key, _check_indexing_error will raise[39;00m
[0;32m   3807[0m     [38;5;66;03m#  InvalidIndexError. Otherwise we fall through and re-raise[39;00m
[0;32m   3808[0m     [38;5;66;03m#  the TypeError.[39;00m
[0;32m   3809[0m     [38;5;28mself[39m[38;5;241m.[39m_check_indexing_error(key)

[1;31mKeyError[0m: 'ModeofTravel'
KeyError: 'ModeofTravel'

